ERROR 2016-02-16 22:13:28,687 base 39102 123145319129088 Internal Server Error: /pdf4/rpc
Traceback (most recent call last):
  File "/Library/Frameworks/Python.framework/Versions/2.7/lib/python2.7/site-packages/django/core/handlers/base.py", line 132, in get_response
    response = wrapped_callback(request, *callback_args, **callback_kwargs)
  File "/Library/Frameworks/Python.framework/Versions/2.7/lib/python2.7/site-packages/django/views/decorators/csrf.py", line 58, in wrapped_view
    return view_func(*args, **kwargs)
  File "/Users/williamxue/Dropbox (MIT)/MIT/SuperUROP/nb/nbproject/apps/rpc/views.py", line 808, in run
    r.content = getattr(MODULE, fctname)(payload, req)
  File "/Users/williamxue/Dropbox (MIT)/MIT/SuperUROP/nb/nbproject/apps/rpc/views.py", line 310, in getObjects
    output[t] = getattr(annotations, "get_"+t)(uid, p2)
  File "/Users/williamxue/Dropbox (MIT)/MIT/SuperUROP/nb/nbproject/apps/base/annotations.py", line 275, in get_file_stats
    return  db.Db().getIndexedObjects(names, "id", from_clause, "true" , (uid,uid, uid, uid, id_ensemble))
  File "/Users/williamxue/Dropbox (MIT)/MIT/SuperUROP/nb/nbproject/apps/base/db.py", line 127, in getIndexedObjects
    c = self.execute(qry, args, connection)
  File "/Users/williamxue/Dropbox (MIT)/MIT/SuperUROP/nb/nbproject/apps/base/db.py", line 49, in execute
    cursor.execute(qry, args)
  File "/Library/Frameworks/Python.framework/Versions/2.7/lib/python2.7/site-packages/django/db/backends/utils.py", line 79, in execute
    return super(CursorDebugWrapper, self).execute(sql, params)
  File "/Library/Frameworks/Python.framework/Versions/2.7/lib/python2.7/site-packages/django/db/backends/utils.py", line 64, in execute
    return self.cursor.execute(sql, params)
  File "/Library/Frameworks/Python.framework/Versions/2.7/lib/python2.7/site-packages/django/db/utils.py", line 98, in __exit__
    six.reraise(dj_exc_type, dj_exc_value, traceback)
  File "/Library/Frameworks/Python.framework/Versions/2.7/lib/python2.7/site-packages/django/db/backends/utils.py", line 64, in execute
    return self.cursor.execute(sql, params)
ProgrammingError: relation "base_v_comment" does not exist
LINE 2: from base_v_comment vc left join (select distinct comment_id...
             ^

ERROR 2016-02-16 22:15:52,563 base 39102 123145310715904 Internal Server Error: /pdf4/rpc
Traceback (most recent call last):
  File "/Library/Frameworks/Python.framework/Versions/2.7/lib/python2.7/site-packages/django/core/handlers/base.py", line 132, in get_response
    response = wrapped_callback(request, *callback_args, **callback_kwargs)
  File "/Library/Frameworks/Python.framework/Versions/2.7/lib/python2.7/site-packages/django/views/decorators/csrf.py", line 58, in wrapped_view
    return view_func(*args, **kwargs)
  File "/Users/williamxue/Dropbox (MIT)/MIT/SuperUROP/nb/nbproject/apps/rpc/views.py", line 808, in run
    r.content = getattr(MODULE, fctname)(payload, req)
  File "/Users/williamxue/Dropbox (MIT)/MIT/SuperUROP/nb/nbproject/apps/rpc/views.py", line 310, in getObjects
    output[t] = getattr(annotations, "get_"+t)(uid, p2)
  File "/Users/williamxue/Dropbox (MIT)/MIT/SuperUROP/nb/nbproject/apps/base/annotations.py", line 275, in get_file_stats
    return  db.Db().getIndexedObjects(names, "id", from_clause, "true" , (uid,uid, uid, uid, id_ensemble))
  File "/Users/williamxue/Dropbox (MIT)/MIT/SuperUROP/nb/nbproject/apps/base/db.py", line 127, in getIndexedObjects
    c = self.execute(qry, args, connection)
  File "/Users/williamxue/Dropbox (MIT)/MIT/SuperUROP/nb/nbproject/apps/base/db.py", line 49, in execute
    cursor.execute(qry, args)
  File "/Library/Frameworks/Python.framework/Versions/2.7/lib/python2.7/site-packages/django/db/backends/utils.py", line 79, in execute
    return super(CursorDebugWrapper, self).execute(sql, params)
  File "/Library/Frameworks/Python.framework/Versions/2.7/lib/python2.7/site-packages/django/db/backends/utils.py", line 64, in execute
    return self.cursor.execute(sql, params)
  File "/Library/Frameworks/Python.framework/Versions/2.7/lib/python2.7/site-packages/django/db/utils.py", line 98, in __exit__
    six.reraise(dj_exc_type, dj_exc_value, traceback)
  File "/Library/Frameworks/Python.framework/Versions/2.7/lib/python2.7/site-packages/django/db/backends/utils.py", line 64, in execute
    return self.cursor.execute(sql, params)
ProgrammingError: relation "base_v_comment" does not exist
LINE 2: from base_v_comment vc left join (select distinct comment_id...
             ^

ERROR 2016-02-16 22:18:27,348 base 39102 123145310715904 Internal Server Error: /pdf4/rpc
Traceback (most recent call last):
  File "/Library/Frameworks/Python.framework/Versions/2.7/lib/python2.7/site-packages/django/core/handlers/base.py", line 132, in get_response
    response = wrapped_callback(request, *callback_args, **callback_kwargs)
  File "/Library/Frameworks/Python.framework/Versions/2.7/lib/python2.7/site-packages/django/views/decorators/csrf.py", line 58, in wrapped_view
    return view_func(*args, **kwargs)
  File "/Users/williamxue/Dropbox (MIT)/MIT/SuperUROP/nb/nbproject/apps/rpc/views.py", line 808, in run
    r.content = getattr(MODULE, fctname)(payload, req)
  File "/Users/williamxue/Dropbox (MIT)/MIT/SuperUROP/nb/nbproject/apps/rpc/views.py", line 310, in getObjects
    output[t] = getattr(annotations, "get_"+t)(uid, p2)
  File "/Users/williamxue/Dropbox (MIT)/MIT/SuperUROP/nb/nbproject/apps/base/annotations.py", line 275, in get_file_stats
    return  db.Db().getIndexedObjects(names, "id", from_clause, "true" , (uid,uid, uid, uid, id_ensemble))
  File "/Users/williamxue/Dropbox (MIT)/MIT/SuperUROP/nb/nbproject/apps/base/db.py", line 127, in getIndexedObjects
    c = self.execute(qry, args, connection)
  File "/Users/williamxue/Dropbox (MIT)/MIT/SuperUROP/nb/nbproject/apps/base/db.py", line 49, in execute
    cursor.execute(qry, args)
  File "/Library/Frameworks/Python.framework/Versions/2.7/lib/python2.7/site-packages/django/db/backends/utils.py", line 79, in execute
    return super(CursorDebugWrapper, self).execute(sql, params)
  File "/Library/Frameworks/Python.framework/Versions/2.7/lib/python2.7/site-packages/django/db/backends/utils.py", line 64, in execute
    return self.cursor.execute(sql, params)
  File "/Library/Frameworks/Python.framework/Versions/2.7/lib/python2.7/site-packages/django/db/utils.py", line 98, in __exit__
    six.reraise(dj_exc_type, dj_exc_value, traceback)
  File "/Library/Frameworks/Python.framework/Versions/2.7/lib/python2.7/site-packages/django/db/backends/utils.py", line 64, in execute
    return self.cursor.execute(sql, params)
ProgrammingError: relation "base_v_comment" does not exist
LINE 2: from base_v_comment vc left join (select distinct comment_id...
             ^

ERROR 2016-02-16 22:18:55,776 base 39102 123145310715904 Internal Server Error: /pdf4/rpc
Traceback (most recent call last):
  File "/Library/Frameworks/Python.framework/Versions/2.7/lib/python2.7/site-packages/django/core/handlers/base.py", line 132, in get_response
    response = wrapped_callback(request, *callback_args, **callback_kwargs)
  File "/Library/Frameworks/Python.framework/Versions/2.7/lib/python2.7/site-packages/django/views/decorators/csrf.py", line 58, in wrapped_view
    return view_func(*args, **kwargs)
  File "/Users/williamxue/Dropbox (MIT)/MIT/SuperUROP/nb/nbproject/apps/rpc/views.py", line 808, in run
    r.content = getattr(MODULE, fctname)(payload, req)
  File "/Users/williamxue/Dropbox (MIT)/MIT/SuperUROP/nb/nbproject/apps/rpc/views.py", line 310, in getObjects
    output[t] = getattr(annotations, "get_"+t)(uid, p2)
  File "/Users/williamxue/Dropbox (MIT)/MIT/SuperUROP/nb/nbproject/apps/base/annotations.py", line 275, in get_file_stats
    return  db.Db().getIndexedObjects(names, "id", from_clause, "true" , (uid,uid, uid, uid, id_ensemble))
  File "/Users/williamxue/Dropbox (MIT)/MIT/SuperUROP/nb/nbproject/apps/base/db.py", line 127, in getIndexedObjects
    c = self.execute(qry, args, connection)
  File "/Users/williamxue/Dropbox (MIT)/MIT/SuperUROP/nb/nbproject/apps/base/db.py", line 49, in execute
    cursor.execute(qry, args)
  File "/Library/Frameworks/Python.framework/Versions/2.7/lib/python2.7/site-packages/django/db/backends/utils.py", line 79, in execute
    return super(CursorDebugWrapper, self).execute(sql, params)
  File "/Library/Frameworks/Python.framework/Versions/2.7/lib/python2.7/site-packages/django/db/backends/utils.py", line 64, in execute
    return self.cursor.execute(sql, params)
  File "/Library/Frameworks/Python.framework/Versions/2.7/lib/python2.7/site-packages/django/db/utils.py", line 98, in __exit__
    six.reraise(dj_exc_type, dj_exc_value, traceback)
  File "/Library/Frameworks/Python.framework/Versions/2.7/lib/python2.7/site-packages/django/db/backends/utils.py", line 64, in execute
    return self.cursor.execute(sql, params)
ProgrammingError: relation "base_v_comment" does not exist
LINE 2: from base_v_comment vc left join (select distinct comment_id...
             ^

